<?xml version="1.0" encoding="utf-8"?>
<!-- This URDF was automatically created by SolidWorks to URDF Exporter! Originally created by Stephen Brawner (brawner@gmail.com) 
     Commit Version: 1.6.0-4-g7f85cfe  Build Version: 1.6.7995.38578
     For more information, please see http://wiki.ros.org/sw_urdf_exporter -->
<robot
  name="armurdf2">
  <link
    name="base_link">
    <inertial>
      <origin
        xyz="5.5511E-17 5.5511E-17 0.07921"
        rpy="0 0 0" />
      <mass
        value="17.682" />
      <inertia
        ixx="0.3246"
        ixy="-2.9144E-17"
        ixz="-3.8784E-17"
        iyy="0.3246"
        iyz="1.5477E-17"
        izz="0.41606" />
    </inertial>
    <visual>
      <origin
        xyz="0 0 0"
        rpy="0 0 0" />
      <geometry>
        <mesh
          filename="package://armurdf2/meshes/base_link.STL" />
      </geometry>
      <material
        name="">
        <color
          rgba="1 1 1 0.35" />
      </material>
    </visual>
    <collision>
      <origin
        xyz="0 0 0"
        rpy="0 0 0" />
      <geometry>
        <mesh
          filename="package://armurdf2/meshes/base_link.STL" />
      </geometry>
    </collision>
  </link>
  <link
    name="link1">
    <inertial>
      <origin
        xyz="1.5626E-10 1.1102E-16 0.37308"
        rpy="0 0 0" />
      <mass
        value="15.531" />
      <inertia
        ixx="0.30108"
        ixy="-1.3459E-09"
        ixz="1.3573E-09"
        iyy="0.32963"
        iyz="-6.2809E-17"
        izz="0.11715" />
    </inertial>
    <visual>
      <origin
        xyz="0 0 0"
        rpy="0 0 0" />
      <geometry>
        <mesh
          filename="package://armurdf2/meshes/link1.STL" />
      </geometry>
      <material
        name="">
        <color
          rgba="1 1 1 0.35" />
      </material>
    </visual>
    <collision>
      <origin
        xyz="0 0 0"
        rpy="0 0 0" />
      <geometry>
        <mesh
          filename="package://armurdf2/meshes/link1.STL" />
      </geometry>
    </collision>
  </link>
  <joint
    name="joint1"
    type="revolute">
    <origin
      xyz="0 0 0"
      rpy="0 0 0" />
    <parent
      link="base_link" />
    <child
      link="link1" />
    <axis
      xyz="0 0 1" />
    <limit
      lower="-3.142"
      upper="3.142"
      effort="160"
      velocity="3" />
    <dynamics
      damping="0"
      friction="0" />
  </joint>
  <link
    name="link2">
    <inertial>
      <origin
        xyz="1.9654E-06 -0.1916 -2.3595E-05"
        rpy="0 0 0" />
      <mass
        value="16.54" />
      <inertia
        ixx="0.7651"
        ixy="-6.0324E-06"
        ixz="-4.0516E-06"
        iyy="0.1679"
        iyz="7.2448E-05"
        izz="0.66407" />
    </inertial>
    <visual>
      <origin
        xyz="0 0 0"
        rpy="0 0 0" />
      <geometry>
        <mesh
          filename="package://armurdf2/meshes/link2.STL" />
      </geometry>
      <material
        name="">
        <color
          rgba="1 1 1 0.35" />
      </material>
    </visual>
    <collision>
      <origin
        xyz="0 0 0"
        rpy="0 0 0" />
      <geometry>
        <mesh
          filename="package://armurdf2/meshes/link2.STL" />
      </geometry>
    </collision>
  </link>
  <joint
    name="joint2"
    type="revolute">
    <origin
      xyz="0 0 0.496"
      rpy="-1.5708 0 0" />
    <parent
      link="link1" />
    <child
      link="link2" />
    <axis
      xyz="0.0031451 0 1" />
    <limit
      lower="-1.57"
      upper="1.309"
      effort="120"
      velocity="3" />
    <dynamics
      damping="0"
      friction="0" />
  </joint>
  <link
    name="link3">
    <inertial>
      <origin
        xyz="0.097689 0.0027227 0.01"
        rpy="0 0 0" />
      <mass
        value="6.4849" />
      <inertia
        ixx="0.034525"
        ixy="-0.0016663"
        ixz="-1.717E-17"
        iyy="0.053729"
        iyz="-6.5698E-18"
        izz="0.063531" />
    </inertial>
    <visual>
      <origin
        xyz="0 0 0"
        rpy="0 0 0" />
      <geometry>
        <mesh
          filename="package://armurdf2/meshes/link3.STL" />
      </geometry>
      <material
        name="">
        <color
          rgba="1 1 1 0.35" />
      </material>
    </visual>
    <collision>
      <origin
        xyz="0 0 0"
        rpy="0 0 0" />
      <geometry>
        <mesh
          filename="package://armurdf2/meshes/link3.STL" />
      </geometry>
    </collision>
  </link>
  <joint
    name="joint3"
    type="revolute">
    <origin
      xyz="0 -0.5 0"
      rpy="0 0 -1.5708" />
    <parent
      link="link2" />
    <child
      link="link3" />
    <axis
      xyz="0 0 1" />
    <limit
      lower="-1.57"
      upper="1.0472"
      effort="40"
      velocity="2.2" />
    <dynamics
      damping="0"
      friction="0" />
  </joint>
  <link
    name="link4">
    <inertial>
      <origin
        xyz="-0.00069175 3.3555E-09 0.14368"
        rpy="0 0 0" />
      <mass
        value="7.0188" />
      <inertia
        ixx="0.067793"
        ixy="-1.9672E-09"
        ixz="0.00041641"
        iyy="0.066756"
        iyz="-4.05E-10"
        izz="0.020743" />
    </inertial>
    <visual>
      <origin
        xyz="0 0 0"
        rpy="0 0 0" />
      <geometry>
        <mesh
          filename="package://armurdf2/meshes/link4.STL" />
      </geometry>
      <material
        name="">
        <color
          rgba="1 1 1 0.35" />
      </material>
    </visual>
    <collision>
      <origin
        xyz="0 0 0"
        rpy="0 0 0" />
      <geometry>
        <mesh
          filename="package://armurdf2/meshes/link4.STL" />
      </geometry>
    </collision>
  </link>
  <joint
    name="joint4"
    type="revolute">
    <origin
      xyz="0.145 0.15744 0.01"
      rpy="-1.5708 0 0" />
    <parent
      link="link3" />
    <child
      link="link4" />
    <axis
      xyz="0 0 1" />
    <limit
      lower="-3.14"
      upper="3.14"
      effort="27"
      velocity="2.3" />
    <dynamics
      damping="0"
      friction="0" />
  </joint>
</robot>